<?xml version="1.0" encoding="UTF-8"?>
<!-- Generated by org.testng.reporters.JUnitReportReporter -->
<testsuite hostname="ADS67" name="exe.Arthadb_Automation" tests="14" failures="0" timestamp="8 Oct 2017 12:30:09 GMT" time="1.746" errors="5">
  <testcase name="ArthaDB_Customer_Details_Update_Check_TC014" time="0.019" classname="exe.Arthadb_Automation"/>
  <testcase name="ArthaDB_PrimaryPhoneNumber_TC013" time="0.030" classname="exe.Arthadb_Automation">
    <error type="junit.framework.AssertionFailedError" message="Customer - PrimaryPhoneNumber check is Failed at SSN=123-45-6789,123-45-6790, expected:&lt;0&gt; but was:&lt;2&gt;">
      <![CDATA[junit.framework.AssertionFailedError: Customer - PrimaryPhoneNumber check is Failed at SSN=123-45-6789,123-45-6790, expected:<0> but was:<2>
	at junit.framework.Assert.fail(Assert.java:57)
	at junit.framework.Assert.failNotEquals(Assert.java:329)
	at junit.framework.Assert.assertEquals(Assert.java:78)
	at junit.framework.Assert.assertEquals(Assert.java:234)
	at exe.Arthadb_Automation.ArthaDB_PrimaryPhoneNumber_TC013(Arthadb_Automation.java:513)
	at sun.reflect.NativeMethodAccessorImpl.invoke0(Native Method)
	at sun.reflect.NativeMethodAccessorImpl.invoke(Unknown Source)
	at sun.reflect.DelegatingMethodAccessorImpl.invoke(Unknown Source)
	at java.lang.reflect.Method.invoke(Unknown Source)
	at org.testng.internal.MethodInvocationHelper.invokeMethod(MethodInvocationHelper.java:80)
	at org.testng.internal.Invoker.invokeMethod(Invoker.java:714)
	at org.testng.internal.Invoker.invokeTestMethod(Invoker.java:901)
	at org.testng.internal.Invoker.invokeTestMethods(Invoker.java:1231)
	at org.testng.internal.TestMethodWorker.invokeTestMethods(TestMethodWorker.java:127)
	at org.testng.internal.TestMethodWorker.run(TestMethodWorker.java:111)
	at org.testng.TestRunner.privateRun(TestRunner.java:767)
	at org.testng.TestRunner.run(TestRunner.java:617)
	at org.testng.SuiteRunner.runTest(SuiteRunner.java:334)
	at org.testng.SuiteRunner.runSequentially(SuiteRunner.java:329)
	at org.testng.SuiteRunner.privateRun(SuiteRunner.java:291)
	at org.testng.SuiteRunner.run(SuiteRunner.java:240)
	at org.testng.SuiteRunnerWorker.runSuite(SuiteRunnerWorker.java:52)
	at org.testng.SuiteRunnerWorker.run(SuiteRunnerWorker.java:86)
	at org.testng.TestNG.runSuitesSequentially(TestNG.java:1198)
	at org.testng.TestNG.runSuitesLocally(TestNG.java:1123)
	at org.testng.TestNG.run(TestNG.java:1031)
	at org.testng.remote.AbstractRemoteTestNG.run(AbstractRemoteTestNG.java:132)
	at org.testng.remote.RemoteTestNG.initAndRun(RemoteTestNG.java:230)
	at org.testng.remote.RemoteTestNG.main(RemoteTestNG.java:76)
]]>
    </error>
  </testcase> <!-- ArthaDB_PrimaryPhoneNumber_TC013 -->
  <testcase name="ArthaDB_Record_Type_Check_TC008" time="0.021" classname="exe.Arthadb_Automation">
    <error type="junit.framework.AssertionFailedError" message="PAYMENTS-Record Type check is Failed at Invoice_Number=J9908844423C102,J9160067066C122,J91606706e6C122, expected:&lt;0&gt; but was:&lt;3&gt;">
      <![CDATA[junit.framework.AssertionFailedError: PAYMENTS-Record Type check is Failed at Invoice_Number=J9908844423C102,J9160067066C122,J91606706e6C122, expected:<0> but was:<3>
	at junit.framework.Assert.fail(Assert.java:57)
	at junit.framework.Assert.failNotEquals(Assert.java:329)
	at junit.framework.Assert.assertEquals(Assert.java:78)
	at junit.framework.Assert.assertEquals(Assert.java:234)
	at exe.Arthadb_Automation.ArthaDB_Record_Type_Check_TC008(Arthadb_Automation.java:336)
	at sun.reflect.NativeMethodAccessorImpl.invoke0(Native Method)
	at sun.reflect.NativeMethodAccessorImpl.invoke(Unknown Source)
	at sun.reflect.DelegatingMethodAccessorImpl.invoke(Unknown Source)
	at java.lang.reflect.Method.invoke(Unknown Source)
	at org.testng.internal.MethodInvocationHelper.invokeMethod(MethodInvocationHelper.java:80)
	at org.testng.internal.Invoker.invokeMethod(Invoker.java:714)
	at org.testng.internal.Invoker.invokeTestMethod(Invoker.java:901)
	at org.testng.internal.Invoker.invokeTestMethods(Invoker.java:1231)
	at org.testng.internal.TestMethodWorker.invokeTestMethods(TestMethodWorker.java:127)
	at org.testng.internal.TestMethodWorker.run(TestMethodWorker.java:111)
	at org.testng.TestRunner.privateRun(TestRunner.java:767)
	at org.testng.TestRunner.run(TestRunner.java:617)
	at org.testng.SuiteRunner.runTest(SuiteRunner.java:334)
	at org.testng.SuiteRunner.runSequentially(SuiteRunner.java:329)
	at org.testng.SuiteRunner.privateRun(SuiteRunner.java:291)
	at org.testng.SuiteRunner.run(SuiteRunner.java:240)
	at org.testng.SuiteRunnerWorker.runSuite(SuiteRunnerWorker.java:52)
	at org.testng.SuiteRunnerWorker.run(SuiteRunnerWorker.java:86)
	at org.testng.TestNG.runSuitesSequentially(TestNG.java:1198)
	at org.testng.TestNG.runSuitesLocally(TestNG.java:1123)
	at org.testng.TestNG.run(TestNG.java:1031)
	at org.testng.remote.AbstractRemoteTestNG.run(AbstractRemoteTestNG.java:132)
	at org.testng.remote.RemoteTestNG.initAndRun(RemoteTestNG.java:230)
	at org.testng.remote.RemoteTestNG.main(RemoteTestNG.java:76)
]]>
    </error>
  </testcase> <!-- ArthaDB_Record_Type_Check_TC008 -->
  <testcase name="ArthaDB_Transaction_Amount_Check_TC006" time="0.019" classname="exe.Arthadb_Automation"/>
  <testcase name="ArthaDB_ChargeType_Check_TC004" time="1.358" classname="exe.Arthadb_Automation"/>
  <testcase name="ArthaDB_Invoice_Number_Check_TC005" time="0.026" classname="exe.Arthadb_Automation"/>
  <testcase name="ArthaDB_Customers_SSN_Check_TC010" time="0.039" classname="exe.Arthadb_Automation">
    <error type="junit.framework.AssertionFailedError" message="CUSTOMERS- SSN check is Failed at CustomerPK=5, expected:&lt;0&gt; but was:&lt;1&gt;">
      <![CDATA[junit.framework.AssertionFailedError: CUSTOMERS- SSN check is Failed at CustomerPK=5, expected:<0> but was:<1>
	at junit.framework.Assert.fail(Assert.java:57)
	at junit.framework.Assert.failNotEquals(Assert.java:329)
	at junit.framework.Assert.assertEquals(Assert.java:78)
	at junit.framework.Assert.assertEquals(Assert.java:234)
	at exe.Arthadb_Automation.ArthaDB_Customers_SSN_Check_TC010(Arthadb_Automation.java:407)
	at sun.reflect.NativeMethodAccessorImpl.invoke0(Native Method)
	at sun.reflect.NativeMethodAccessorImpl.invoke(Unknown Source)
	at sun.reflect.DelegatingMethodAccessorImpl.invoke(Unknown Source)
	at java.lang.reflect.Method.invoke(Unknown Source)
	at org.testng.internal.MethodInvocationHelper.invokeMethod(MethodInvocationHelper.java:80)
	at org.testng.internal.Invoker.invokeMethod(Invoker.java:714)
	at org.testng.internal.Invoker.invokeTestMethod(Invoker.java:901)
	at org.testng.internal.Invoker.invokeTestMethods(Invoker.java:1231)
	at org.testng.internal.TestMethodWorker.invokeTestMethods(TestMethodWorker.java:127)
	at org.testng.internal.TestMethodWorker.run(TestMethodWorker.java:111)
	at org.testng.TestRunner.privateRun(TestRunner.java:767)
	at org.testng.TestRunner.run(TestRunner.java:617)
	at org.testng.SuiteRunner.runTest(SuiteRunner.java:334)
	at org.testng.SuiteRunner.runSequentially(SuiteRunner.java:329)
	at org.testng.SuiteRunner.privateRun(SuiteRunner.java:291)
	at org.testng.SuiteRunner.run(SuiteRunner.java:240)
	at org.testng.SuiteRunnerWorker.runSuite(SuiteRunnerWorker.java:52)
	at org.testng.SuiteRunnerWorker.run(SuiteRunnerWorker.java:86)
	at org.testng.TestNG.runSuitesSequentially(TestNG.java:1198)
	at org.testng.TestNG.runSuitesLocally(TestNG.java:1123)
	at org.testng.TestNG.run(TestNG.java:1031)
	at org.testng.remote.AbstractRemoteTestNG.run(AbstractRemoteTestNG.java:132)
	at org.testng.remote.RemoteTestNG.initAndRun(RemoteTestNG.java:230)
	at org.testng.remote.RemoteTestNG.main(RemoteTestNG.java:76)
]]>
    </error>
  </testcase> <!-- ArthaDB_Customers_SSN_Check_TC010 -->
  <testcase name="ArthaDB_ProdCodes_Check_TC001" time="0.053" classname="exe.Arthadb_Automation"/>
  <testcase name="ArthaDB_Customer_First_Last_Name_Check_TC009" time="0.031" classname="exe.Arthadb_Automation">
    <error type="junit.framework.AssertionFailedError" message="CUSTOMERS-First &amp; Last Name check is Failed at SSN=123-45-6791,123-45-6792, expected:&lt;0&gt; but was:&lt;2&gt;">
      <![CDATA[junit.framework.AssertionFailedError: CUSTOMERS-First & Last Name check is Failed at SSN=123-45-6791,123-45-6792, expected:<0> but was:<2>
	at junit.framework.Assert.fail(Assert.java:57)
	at junit.framework.Assert.failNotEquals(Assert.java:329)
	at junit.framework.Assert.assertEquals(Assert.java:78)
	at junit.framework.Assert.assertEquals(Assert.java:234)
	at exe.Arthadb_Automation.ArthaDB_Customer_First_Last_Name_Check_TC009(Arthadb_Automation.java:371)
	at sun.reflect.NativeMethodAccessorImpl.invoke0(Native Method)
	at sun.reflect.NativeMethodAccessorImpl.invoke(Unknown Source)
	at sun.reflect.DelegatingMethodAccessorImpl.invoke(Unknown Source)
	at java.lang.reflect.Method.invoke(Unknown Source)
	at org.testng.internal.MethodInvocationHelper.invokeMethod(MethodInvocationHelper.java:80)
	at org.testng.internal.Invoker.invokeMethod(Invoker.java:714)
	at org.testng.internal.Invoker.invokeTestMethod(Invoker.java:901)
	at org.testng.internal.Invoker.invokeTestMethods(Invoker.java:1231)
	at org.testng.internal.TestMethodWorker.invokeTestMethods(TestMethodWorker.java:127)
	at org.testng.internal.TestMethodWorker.run(TestMethodWorker.java:111)
	at org.testng.TestRunner.privateRun(TestRunner.java:767)
	at org.testng.TestRunner.run(TestRunner.java:617)
	at org.testng.SuiteRunner.runTest(SuiteRunner.java:334)
	at org.testng.SuiteRunner.runSequentially(SuiteRunner.java:329)
	at org.testng.SuiteRunner.privateRun(SuiteRunner.java:291)
	at org.testng.SuiteRunner.run(SuiteRunner.java:240)
	at org.testng.SuiteRunnerWorker.runSuite(SuiteRunnerWorker.java:52)
	at org.testng.SuiteRunnerWorker.run(SuiteRunnerWorker.java:86)
	at org.testng.TestNG.runSuitesSequentially(TestNG.java:1198)
	at org.testng.TestNG.runSuitesLocally(TestNG.java:1123)
	at org.testng.TestNG.run(TestNG.java:1031)
	at org.testng.remote.AbstractRemoteTestNG.run(AbstractRemoteTestNG.java:132)
	at org.testng.remote.RemoteTestNG.initAndRun(RemoteTestNG.java:230)
	at org.testng.remote.RemoteTestNG.main(RemoteTestNG.java:76)
]]>
    </error>
  </testcase> <!-- ArthaDB_Customer_First_Last_Name_Check_TC009 -->
  <testcase name="ArthaDB_AuditDates_Check_TC002" time="0.027" classname="exe.Arthadb_Automation"/>
  <testcase name="ArthaDB_Record_Type_Check_TC011" time="0.039" classname="exe.Arthadb_Automation"/>
  <testcase name="ArthaDB_Account_Number_Check_TC003" time="0.028" classname="exe.Arthadb_Automation"/>
  <testcase name="ArthaDB_Premise_City_Check_TC012" time="0.032" classname="exe.Arthadb_Automation"/>
  <testcase name="ArthaDB_ChargeSign_Check_TC007" time="0.024" classname="exe.Arthadb_Automation">
    <error type="junit.framework.AssertionFailedError" message="PAYMENTS-Charge Sign Codes check is Failed at Account_Number=ACCD101N8776123, expected:&lt;0&gt; but was:&lt;1&gt;">
      <![CDATA[junit.framework.AssertionFailedError: PAYMENTS-Charge Sign Codes check is Failed at Account_Number=ACCD101N8776123, expected:<0> but was:<1>
	at junit.framework.Assert.fail(Assert.java:57)
	at junit.framework.Assert.failNotEquals(Assert.java:329)
	at junit.framework.Assert.assertEquals(Assert.java:78)
	at junit.framework.Assert.assertEquals(Assert.java:234)
	at exe.Arthadb_Automation.ArthaDB_ChargeSign_Check_TC007(Arthadb_Automation.java:300)
	at sun.reflect.NativeMethodAccessorImpl.invoke0(Native Method)
	at sun.reflect.NativeMethodAccessorImpl.invoke(Unknown Source)
	at sun.reflect.DelegatingMethodAccessorImpl.invoke(Unknown Source)
	at java.lang.reflect.Method.invoke(Unknown Source)
	at org.testng.internal.MethodInvocationHelper.invokeMethod(MethodInvocationHelper.java:80)
	at org.testng.internal.Invoker.invokeMethod(Invoker.java:714)
	at org.testng.internal.Invoker.invokeTestMethod(Invoker.java:901)
	at org.testng.internal.Invoker.invokeTestMethods(Invoker.java:1231)
	at org.testng.internal.TestMethodWorker.invokeTestMethods(TestMethodWorker.java:127)
	at org.testng.internal.TestMethodWorker.run(TestMethodWorker.java:111)
	at org.testng.TestRunner.privateRun(TestRunner.java:767)
	at org.testng.TestRunner.run(TestRunner.java:617)
	at org.testng.SuiteRunner.runTest(SuiteRunner.java:334)
	at org.testng.SuiteRunner.runSequentially(SuiteRunner.java:329)
	at org.testng.SuiteRunner.privateRun(SuiteRunner.java:291)
	at org.testng.SuiteRunner.run(SuiteRunner.java:240)
	at org.testng.SuiteRunnerWorker.runSuite(SuiteRunnerWorker.java:52)
	at org.testng.SuiteRunnerWorker.run(SuiteRunnerWorker.java:86)
	at org.testng.TestNG.runSuitesSequentially(TestNG.java:1198)
	at org.testng.TestNG.runSuitesLocally(TestNG.java:1123)
	at org.testng.TestNG.run(TestNG.java:1031)
	at org.testng.remote.AbstractRemoteTestNG.run(AbstractRemoteTestNG.java:132)
	at org.testng.remote.RemoteTestNG.initAndRun(RemoteTestNG.java:230)
	at org.testng.remote.RemoteTestNG.main(RemoteTestNG.java:76)
]]>
    </error>
  </testcase> <!-- ArthaDB_ChargeSign_Check_TC007 -->
</testsuite> <!-- exe.Arthadb_Automation -->
